<?xml version="1.0" ?>
<!-- =================================================================================== -->
<!-- |    This document was autogenerated by xacro from mab_ros2_control/urdf/mab_three_axis.urdf.xacro | -->
<!-- |    EDITING THIS FILE BY HAND IS NOT RECOMMENDED                                 | -->
<!-- =================================================================================== -->
<robot name="mab_three_axis_rehab_robot">
  <material name="carbon">
    <color rgba="0.22 0.25 0.30 1.0"/>
  </material>
  <material name="signal">
    <color rgba="0.85 0.43 0.14 1.0"/>
  </material>
  <link name="base_link">
    <visual>
      <geometry>
        <box size="0.18 0.12 0.04"/>
      </geometry>
      <material name="carbon"/>
    </visual>
    <collision>
      <geometry>
        <box size="0.18 0.12 0.04"/>
      </geometry>
    </collision>
    <inertial>
      <mass value="1.0"/>
      <origin xyz="0 0 0"/>
      <inertia ixx="0.01" ixy="0.0" ixz="0.0" iyy="0.01" iyz="0.0" izz="0.01"/>
    </inertial>
  </link>
  <link name="link_1">
    <visual>
      <geometry>
        <cylinder length="0.18" radius="0.025"/>
      </geometry>
      <origin rpy="0 0 0" xyz="0 0 0.09"/>
      <material name="signal"/>
    </visual>
    <collision>
      <geometry>
        <cylinder length="0.18" radius="0.025"/>
      </geometry>
      <origin rpy="0 0 0" xyz="0 0 0.09"/>
    </collision>
    <inertial>
      <mass value="0.4"/>
      <origin xyz="0 0 0.09"/>
      <inertia ixx="0.002" ixy="0.0" ixz="0.0" iyy="0.002" iyz="0.0" izz="0.001"/>
    </inertial>
  </link>
  <link name="link_2">
    <visual>
      <geometry>
        <cylinder length="0.16" radius="0.022"/>
      </geometry>
      <origin rpy="0 0 0" xyz="0 0 0.08"/>
      <material name="signal"/>
    </visual>
    <collision>
      <geometry>
        <cylinder length="0.16" radius="0.022"/>
      </geometry>
      <origin rpy="0 0 0" xyz="0 0 0.08"/>
    </collision>
    <inertial>
      <mass value="0.3"/>
      <origin xyz="0 0 0.08"/>
      <inertia ixx="0.0016" ixy="0.0" ixz="0.0" iyy="0.0016" iyz="0.0" izz="0.0008"/>
    </inertial>
  </link>
  <link name="link_3">
    <visual>
      <geometry>
        <cylinder length="0.14" radius="0.02"/>
      </geometry>
      <origin rpy="0 0 0" xyz="0 0 0.07"/>
      <material name="signal"/>
    </visual>
    <collision>
      <geometry>
        <cylinder length="0.14" radius="0.02"/>
      </geometry>
      <origin rpy="0 0 0" xyz="0 0 0.07"/>
    </collision>
    <inertial>
      <mass value="0.25"/>
      <origin xyz="0 0 0.07"/>
      <inertia ixx="0.0012" ixy="0.0" ixz="0.0" iyy="0.0012" iyz="0.0" izz="0.0006"/>
    </inertial>
  </link>
  <joint name="joint_1" type="revolute">
    <parent link="base_link"/>
    <child link="link_1"/>
    <origin rpy="0 0 0" xyz="0 0 0.02"/>
    <axis xyz="0 0 1"/>
    <limit effort="40.0" lower="-6.283" upper="6.283" velocity="20.0"/>
  </joint>
  <joint name="joint_2" type="revolute">
    <parent link="link_1"/>
    <child link="link_2"/>
    <origin rpy="0 0 0" xyz="0 0 0.18"/>
    <axis xyz="0 1 0"/>
    <limit effort="40.0" lower="-6.283" upper="6.283" velocity="20.0"/>
  </joint>
  <joint name="joint_3" type="revolute">
    <parent link="link_2"/>
    <child link="link_3"/>
    <origin rpy="0 0 0" xyz="0 0 0.16"/>
    <axis xyz="0 1 0"/>
    <limit effort="40.0" lower="-6.283" upper="6.283" velocity="20.0"/>
  </joint>
  <ros2_control name="mab_hardware" type="system">
    <hardware>
      <plugin>mab_ros2_control/MABSystemHardware</plugin>
      <param name="bus">USB</param>
      <param name="data_rate">8M</param>
      <param name="use_pds">true</param>
      <param name="use_regular_can_frames">true</param>
      <param name="pds_id">100</param>
      <param name="power_stage_socket">2</param>
      <param name="telemetry_divider">50</param>
      <param name="auto_enable_power_stage">true</param>
      <param name="disable_power_stage_on_deactivate">false</param>
      <param name="zero_on_activate">false</param>
      <param name="allow_no_connected_drives">true</param>
      <param name="save_md_configuration_to_flash">false</param>
      <param name="hold_position_on_activate_ms">3000</param>
      <param name="maintenance_reload_enabled">true</param>
      <param name="maintenance_restore_controller">previous</param>
      <param name="maintenance_service_timeout_ms">3000</param>
      <param name="md_torque_bandwidth_hz">1000.0</param>
      <param name="md_can_watchdog_ms">nan</param>
      <param name="md_limit_max_torque">40.0</param>
      <param name="md_limit_max_velocity">20.0</param>
      <param name="md_limit_max_acceleration">60.0</param>
      <param name="md_limit_max_deceleration">60.0</param>
      <param name="md_limit_position_min">-6.283</param>
      <param name="md_limit_position_max">6.283</param>
      <param name="md_profile_velocity">12.0</param>
      <param name="md_profile_acceleration">30.0</param>
      <param name="md_profile_deceleration">30.0</param>
      <param name="md_profile_quick_stop_deceleration">50.0</param>
      <param name="md_position_pid_kp">10.5</param>
      <param name="md_position_pid_ki">1.5</param>
      <param name="md_position_pid_kd">0.0</param>
      <param name="md_position_pid_windup">1.0</param>
      <param name="md_velocity_pid_kp">0.1</param>
      <param name="md_velocity_pid_ki">0.0005</param>
      <param name="md_velocity_pid_kd">0.0</param>
      <param name="md_velocity_pid_windup">0.25</param>
      <param name="md_impedance_kp">0.75</param>
      <param name="md_impedance_kd">0.02</param>
    </hardware>
    <joint name="joint_1">
      <!-- Joint 1 uses MD0037 with an MA-p-45-36_KV80 motor and an external 38:1 reduction. -->
      <param name="can_id">37</param>
      <param name="motor_name">MA-p-45-36_KV80</param>
      <param name="gear_ratio">0.02631578947368421</param>
      <param name="pole_pairs">14</param>
      <param name="kv">80</param>
      <param name="torque_constant">0.11</param>
      <param name="max_current">15.0</param>
      <param name="torque_bandwidth_hz">1000.0</param>
      <param name="friction">0.0</param>
      <param name="stiction">0.0</param>
      <param name="motor_calibration_mode">0</param>
      <param name="shutdown_temp">80.0</param>
      <param name="limit_max_torque">40.0</param>
      <param name="limit_max_velocity">20.0</param>
      <param name="limit_position_min">-6.283</param>
      <param name="limit_position_max">6.283</param>
      <param name="limit_max_acceleration">60.0</param>
      <param name="limit_max_deceleration">60.0</param>
      <param name="profile_velocity">12.0</param>
      <param name="profile_acceleration">30.0</param>
      <param name="profile_deceleration">30.0</param>
      <param name="profile_quick_stop_deceleration">50.0</param>
      <param name="output_encoder">0</param>
      <param name="output_encoder_default_baud">0</param>
      <param name="output_encoder_mode">0</param>
      <param name="output_encoder_calibration_mode">0</param>
      <param name="position_pid_kp">10.5</param>
      <param name="position_pid_ki">1.5</param>
      <param name="position_pid_kd">0.0</param>
      <param name="position_pid_windup">1.0</param>
      <param name="velocity_pid_kp">0.1</param>
      <param name="velocity_pid_ki">0.0005</param>
      <param name="velocity_pid_kd">0.0</param>
      <param name="velocity_pid_windup">0.25</param>
      <param name="impedance_kp">0.75</param>
      <param name="impedance_kd">0.02</param>
      <param name="user_gpio_configuration">0</param>
      <param name="reverse_direction">0</param>
      <param name="shunt_resistance">0.004</param>
      <command_interface name="position"/>
      <command_interface name="velocity"/>
      <state_interface name="position"/>
      <state_interface name="velocity"/>
      <state_interface name="effort"/>
      <state_interface name="temperature"/>
    </joint>
    <joint name="joint_2">
      <!-- Joint 2 uses MD0939 with an MA-p-40_10_K170 motor and an external 10:1 reduction. -->
      <param name="can_id">939</param>
      <param name="motor_name">MA-p-40_10_K170</param>
      <param name="gear_ratio">0.1</param>
      <param name="pole_pairs">14</param>
      <param name="kv">170</param>
      <param name="torque_constant">0.056</param>
      <param name="max_current">15.0</param>
      <param name="torque_bandwidth_hz">1000.0</param>
      <param name="friction">0.0</param>
      <param name="stiction">0.0</param>
      <param name="motor_calibration_mode">0</param>
      <param name="shutdown_temp">80.0</param>
      <param name="limit_max_torque">40.0</param>
      <param name="limit_max_velocity">20.0</param>
      <param name="limit_position_min">-6.283</param>
      <param name="limit_position_max">6.283</param>
      <param name="limit_max_acceleration">60.0</param>
      <param name="limit_max_deceleration">60.0</param>
      <param name="profile_velocity">12.0</param>
      <param name="profile_acceleration">30.0</param>
      <param name="profile_deceleration">30.0</param>
      <param name="profile_quick_stop_deceleration">50.0</param>
      <param name="output_encoder">0</param>
      <param name="output_encoder_default_baud">0</param>
      <param name="output_encoder_mode">0</param>
      <param name="output_encoder_calibration_mode">0</param>
      <param name="position_pid_kp">3.5</param>
      <param name="position_pid_ki">0.5</param>
      <param name="position_pid_kd">0.0</param>
      <param name="position_pid_windup">1.0</param>
      <param name="velocity_pid_kp">0.6</param>
      <param name="velocity_pid_ki">0.0005</param>
      <param name="velocity_pid_kd">0.0</param>
      <param name="velocity_pid_windup">0.25</param>
      <param name="impedance_kp">1.75</param>
      <param name="impedance_kd">0.02</param>
      <param name="user_gpio_configuration">0</param>
      <param name="reverse_direction">0</param>
      <param name="shunt_resistance">0.004</param>
      <command_interface name="position"/>
      <command_interface name="velocity"/>
      <state_interface name="position"/>
      <state_interface name="velocity"/>
      <state_interface name="effort"/>
      <state_interface name="temperature"/>
    </joint>
    <joint name="joint_3">
      <!-- Joint 3 uses MD0941 with an MA-p-40_10_K170 motor and an external 10:1 reduction. -->
      <param name="can_id">941</param>
      <param name="motor_name">MA-p-40_10_K170</param>
      <param name="gear_ratio">0.1</param>
      <param name="pole_pairs">14</param>
      <param name="kv">170</param>
      <param name="torque_constant">0.056</param>
      <param name="max_current">15.0</param>
      <param name="torque_bandwidth_hz">1000.0</param>
      <param name="friction">0.0</param>
      <param name="stiction">0.0</param>
      <param name="motor_calibration_mode">0</param>
      <param name="shutdown_temp">80.0</param>
      <param name="limit_max_torque">40.0</param>
      <param name="limit_max_velocity">20.0</param>
      <param name="limit_position_min">-6.283</param>
      <param name="limit_position_max">6.283</param>
      <param name="limit_max_acceleration">60.0</param>
      <param name="limit_max_deceleration">60.0</param>
      <param name="profile_velocity">12.0</param>
      <param name="profile_acceleration">30.0</param>
      <param name="profile_deceleration">30.0</param>
      <param name="profile_quick_stop_deceleration">50.0</param>
      <param name="output_encoder">0</param>
      <param name="output_encoder_default_baud">0</param>
      <param name="output_encoder_mode">0</param>
      <param name="output_encoder_calibration_mode">0</param>
      <param name="position_pid_kp">3.5</param>
      <param name="position_pid_ki">0.5</param>
      <param name="position_pid_kd">0.0</param>
      <param name="position_pid_windup">1.0</param>
      <param name="velocity_pid_kp">0.6</param>
      <param name="velocity_pid_ki">0.0005</param>
      <param name="velocity_pid_kd">0.0</param>
      <param name="velocity_pid_windup">0.25</param>
      <param name="impedance_kp">1.75</param>
      <param name="impedance_kd">0.02</param>
      <param name="user_gpio_configuration">0</param>
      <param name="reverse_direction">0</param>
      <param name="shunt_resistance">0.004</param>
      <command_interface name="position"/>
      <command_interface name="velocity"/>
      <state_interface name="position"/>
      <state_interface name="velocity"/>
      <state_interface name="effort"/>
      <state_interface name="temperature"/>
    </joint>
    <sensor name="mab_power_stage">
      <state_interface name="bus_voltage"/>
      <state_interface name="pds_temperature"/>
      <state_interface name="pds_temperature_limit"/>
      <state_interface name="output_voltage"/>
      <state_interface name="load_current"/>
      <state_interface name="power_stage_temperature"/>
      <state_interface name="power_stage_temperature_limit"/>
      <state_interface name="enabled"/>
    </sensor>
  </ros2_control>
</robot>
