<?xml version="1.0" ?>
<robot name="complete_system_urdf" xmlns:xacro="http://www.ros.org/wiki/xacro">

<xacro:include filename="$(find complete_system_urdf_description)/urdf/materials.xacro" />
<xacro:include filename="$(find complete_system_urdf_description)/urdf/complete_system_urdf.ros2control" />
<xacro:include filename="$(find complete_system_urdf_description)/urdf/complete_system_urdf.gazebo" />
<link name="base_link">
  <inertial>
    <origin xyz="-0.029198791382221607 0.22398134735531283 -0.09489285599188749" rpy="0 0 0"/>
    <mass value="1.4539912251743274"/>
    <inertia ixx="0.01021" iyy="0.007322" izz="0.007077" ixy="-0.00011" iyz="-0.000354" ixz="-6e-06"/>
  </inertial>
  <visual>
    <origin xyz="0 0 0" rpy="0 0 0"/>
    <geometry>
      <mesh filename="file://$(find complete_system_urdf_description)/meshes/base_link.stl" scale="0.001 0.001 0.001"/>
    </geometry>
    <material name="silver"/>
  </visual>
  <collision>
    <origin xyz="0 0 0" rpy="0 0 0"/>
    <geometry>
      <mesh filename="file://$(find complete_system_urdf_description)/meshes/base_link.stl" scale="0.001 0.001 0.001"/>
    </geometry>
  </collision>
</link>

<link name="Body1__1__1">
  <inertial>
    <origin xyz="0.06216244862253437 -0.11070935032705907 -0.015943553429518482" rpy="0 0 0"/>
    <mass value="0.7966630718351357"/>
    <inertia ixx="0.007599" iyy="0.00742" izz="0.009713" ixy="0.003864" iyz="0.002148" ixz="-0.001823"/>
  </inertial>
  <visual>
    <origin xyz="0.029967 -0.176148 -0.028781" rpy="0 0 0"/>
    <geometry>
      <mesh filename="file://$(find complete_system_urdf_description)/meshes/Body1__1__1.stl" scale="0.001 0.001 0.001"/>
    </geometry>
    <material name="silver"/>
  </visual>
  <collision>
    <origin xyz="0.029967 -0.176148 -0.028781" rpy="0 0 0"/>
    <geometry>
      <mesh filename="file://$(find complete_system_urdf_description)/meshes/Body1__1__1.stl" scale="0.001 0.001 0.001"/>
    </geometry>
  </collision>
</link>

<link name="Body6__2__1">
  <inertial>
    <origin xyz="-0.04701173824953431 0.00021188777037241951 -0.08678119435178486" rpy="0 0 0"/>
    <mass value="0.4312680820281363"/>
    <inertia ixx="0.003443" iyy="0.004987" izz="0.001932" ixy="6e-06" iyz="4e-06" ixz="-0.002082"/>
  </inertial>
  <visual>
    <origin xyz="-0.12195 0.036145 -0.031848" rpy="0 0 0"/>
    <geometry>
      <mesh filename="file://$(find complete_system_urdf_description)/meshes/Body6__2__1.stl" scale="0.001 0.001 0.001"/>
    </geometry>
    <material name="silver"/>
  </visual>
  <collision>
    <origin xyz="-0.12195 0.036145 -0.031848" rpy="0 0 0"/>
    <geometry>
      <mesh filename="file://$(find complete_system_urdf_description)/meshes/Body6__2__1.stl" scale="0.001 0.001 0.001"/>
    </geometry>
  </collision>
</link>

<link name="Body2__3__1">
  <inertial>
    <origin xyz="0.0057898842437530545 -0.028375722981906756 0.03732478318815739" rpy="0 0 0"/>
    <mass value="0.3084742163632643"/>
    <inertia ixx="0.001918" iyy="0.001613" izz="0.000704" ixy="-6.9e-05" iyz="0.000608" ixz="0.000126"/>
  </inertial>
  <visual>
    <origin xyz="0.030254 0.036145 0.138152" rpy="0 0 0"/>
    <geometry>
      <mesh filename="file://$(find complete_system_urdf_description)/meshes/Body2__3__1.stl" scale="0.001 0.001 0.001"/>
    </geometry>
    <material name="silver"/>
  </visual>
  <collision>
    <origin xyz="0.030254 0.036145 0.138152" rpy="0 0 0"/>
    <geometry>
      <mesh filename="file://$(find complete_system_urdf_description)/meshes/Body2__3__1.stl" scale="0.001 0.001 0.001"/>
    </geometry>
  </collision>
</link>

<joint name="joint_1" type="revolute">
  <origin xyz="-0.029967 0.176148 0.028781" rpy="0 0 0"/>
  <parent link="base_link"/>
  <child link="Body1__1__1"/>
  <axis xyz="-0.0 1.0 -0.0"/>
  <limit upper="1.22173" lower="-1.22173" effort="100" velocity="100"/>
</joint>

<joint name="joint_2" type="revolute">
  <origin xyz="0.151917 -0.212293 0.003067" rpy="0 0 0"/>
  <parent link="Body1__1__1"/>
  <child link="Body6__2__1"/>
  <axis xyz="-1.0 0.0 -0.0"/>
  <limit upper="0.523599" lower="-0.523599" effort="100" velocity="100"/>
</joint>

<joint name="joint_3" type="revolute">
  <origin xyz="-0.152204 0.0 -0.17" rpy="0 0 0"/>
  <parent link="Body6__2__1"/>
  <child link="Body2__3__1"/>
  <axis xyz="-0.0 0.0 1.0"/>
  <limit upper="1.047198" lower="-1.047198" effort="100" velocity="100"/>
</joint>

</robot>
